<?xml version="1.0"?>
<!-- Open_Manipulator Chain -->

<robot xmlns:xacro="http://ros.org/wiki/xacro">

  <!-- Link 1 -->
  <link name="arm2_link1">
    <visual>
      <origin xyz="0 0 0" rpy="0 0 0"/>
      <geometry>
        <mesh filename="package://open_manipulator_description/meshes/chain_link1.stl" scale="0.001 0.001 0.001"/>
      </geometry>
      <material name="grey"/>
    </visual>

    <collision>
      <origin xyz="0 0 0" rpy="0 0 0"/>
      <geometry>
        <mesh filename="package://open_manipulator_description/meshes/chain_link1.stl" scale="0.001 0.001 0.001"/>
      </geometry>
    </collision>

    <inertial>
      <origin xyz="3.0876154e-04 0.0000000e+00 -1.2176461e-04" />
      <mass value="7.9119962e-02" />
      <inertia ixx="1.2505234e-05" ixy="0.0" ixz="-1.7855208e-07"
               iyy="2.1898364e-05" iyz="0.0"
               izz="1.9267361e-05" />
    </inertial>
  </link>

  <!-- Joint 1 -->
  <joint name="arm2_joint1" type="revolute">
    <parent link="arm2_link1"/>
    <child link="arm2_link2"/>
    <origin xyz="0.012 0.0 0.022" rpy="0 0 0"/>
    <axis xyz="0 0 1"/>
    <limit velocity="4.8" effort="1" lower="${-pi*0.9}" upper="${pi*0.9}" />
  </joint>

  <!--  Link 2 -->
  <link name="arm2_link2">
    <visual>
      <origin xyz="0 0 0.019" rpy="0 0 0"/>
      <geometry>
        <mesh filename="package://open_manipulator_description/meshes/chain_link2.stl" scale="0.001 0.001 0.001"/>
      </geometry>
      <material name="grey"/>
    </visual>

    <collision>
      <origin xyz="0 0 0.019" rpy="0 0 0"/>
      <geometry>
        <mesh filename="package://open_manipulator_description/meshes/chain_link2.stl" scale="0.001 0.001 0.001"/>
      </geometry>
    </collision>

    <inertial>
      <origin xyz="-3.0184870e-04 5.4043684e-04 0.047433464"/>
      <mass value="9.8406837e-02" />
      <inertia ixx="3.4543422e-05" ixy="-1.6031095e-08" ixz="-3.8375155e-07"
               iyy="3.2689329e-05" iyz="2.8511935e-08"
               izz="1.8850320e-05" />
    </inertial>
  </link>

  <!--  Joint 2 -->
  <joint name="arm2_joint2" type="revolute">
    <parent link="arm2_link2"/>
    <child link="arm2_link3"/>
    <origin xyz="0.0 0.0 0.0595" rpy="0 0 0"/>
    <axis xyz="0 1 0"/>
    <limit velocity="4.8" effort="1" lower="${-pi*0.57}" upper="${pi*0.5}" />
  </joint>

  <!--  Link 3 -->
  <link name="arm2_link3">
    <visual>
      <origin xyz="0 0 0" rpy="0 0 0"/>
      <geometry>
        <mesh filename="package://open_manipulator_description/meshes/chain_link3.stl" scale="0.001 0.001 0.001"/>
      </geometry>
      <material name="grey"/>
    </visual>

    <collision>
      <origin xyz="0 0 0" rpy="0 0 0"/>
      <geometry>
        <mesh filename="package://open_manipulator_description/meshes/chain_link3.stl" scale="0.001 0.001 0.001"/>
      </geometry>
    </collision>

    <inertial>
      <origin xyz="1.0308393e-02 3.7743363e-04 1.0170197e-01" />
      <mass value="1.3850917e-01" />
      <inertia ixx="3.3055381e-04" ixy="-9.7940978e-08" ixz="-3.8505711e-05"
               iyy="3.4290447e-04" iyz="-1.5717516e-06"
               izz="6.0346498e-05" />
    </inertial>
  </link>

  <!--  Joint 3 -->
  <joint name="arm2_joint3" type="revolute">
    <parent link="arm2_link3"/>
    <child link="arm2_link4"/>
    <origin xyz="0.024 0 0.128" rpy="0 0 0"/>
    <axis xyz="0 1 0"/>
    <limit velocity="4.8" effort="1" lower="${-pi*0.3}" upper="${pi*0.44}" />
  </joint>

  <!--  Link 4 -->
  <link name="arm2_link4">
    <visual>
      <origin xyz="0 0 0" rpy="0 0 0"/>
      <geometry>
        <mesh filename="package://open_manipulator_description/meshes/chain_link4.stl" scale="0.001 0.001 0.001"/>
      </geometry>
      <material name="grey"/>
    </visual>

    <collision>
      <origin xyz="0 0 0" rpy="0 0 0"/>
      <geometry>
        <mesh filename="package://open_manipulator_description/meshes/chain_link4.stl" scale="0.001 0.001 0.001"/>
      </geometry>
    </collision>

    <inertial>
      <origin xyz="9.0909590e-02 3.8929816e-04 2.2413279e-04" />
      <mass value="1.3274562e-01" />
      <inertia ixx="3.0654178e-05" ixy="-1.2764155e-06" ixz="-2.6874417e-07"
               iyy="2.4230292e-04" iyz="1.1559550e-08"
               izz="2.5155057e-04" />
    </inertial>
  </link>

  <!--  Joint 4 -->
  <joint name="arm2_joint4" type="revolute">
    <parent link="arm2_link4"/>
    <child link="arm2_link5"/>
    <origin xyz="0.124 0.0 0.0" rpy="0 0 0"/>
    <axis xyz="0 1 0"/>
    <limit velocity="4.8" effort="1" lower="${-pi*0.57}" upper="${pi*0.65}" />
  </joint>

  <!--  Link 5 -->
  <link name="arm2_link5">
    <visual>
      <origin xyz="0 0 0" rpy="0 0 0"/>
      <geometry>
        <mesh filename="package://open_manipulator_description/meshes/chain_link_5_1.stl" scale="1 1 1"/>
      </geometry>
      <material name="grey"/>
    </visual>

    <collision>
      <origin xyz="0 0 0" rpy="0 0 0"/>
      <geometry>
        <mesh filename="package://open_manipulator_description/meshes/chain_link_5_1.stl" scale="1 1 1"/>
      </geometry>
    </collision>

    <inertial>
      <origin xyz="4.4206755e-02 3.6839985e-07 8.9142216e-03" />
      <mass value="1.4327573e-01" />
      <inertia ixx="8.0870749e-05" ixy="0.0" ixz="-1.0157896e-06"
               iyy="7.5980465e-05" iyz="0.0"
               izz="9.3127351e-05" />
    </inertial>
  </link>

  <!-- Virtual roll joint -->
  <joint name="arm2_virtual_roll_joint" type="revolute">
    <limit lower="-3.1415" upper="3.1415" effort="1.0" velocity="3.14"/>
    <parent link="arm2_link5"/>
    <child link="arm2_virtual_roll_link"/>
    <axis xyz="1 0 0"/>
    <origin xyz="0.0578 0.0 0.024" rpy="0 0 0"/>
    <dynamics damping="0.0" friction="0.0"/>
  </joint>

  <!-- Virtual roll link -->
  <link name="arm2_virtual_roll_link">
    <visual>
      <origin xyz="0.0022 0 0.0" rpy="0 0 0"/>
      <geometry>
        <mesh filename="package://open_manipulator_description/meshes/chain_link_5_2.STL" scale="1 1 1"/>
      </geometry>
      <material name="grey"/>
     </visual>

    <inertial>
      <origin xyz="0 0 0" />
      <mass value="1.0e-03" />
      <inertia ixx="1.0e-03" ixy="0.0" ixz="0.0"
               iyy="1.0e-03" iyz="0.0"
               izz="1.0e-03" />
    </inertial>
  </link>

  <!-- Virtual yaw joint -->
  <joint name="arm2_virtual_yaw_joint" type="revolute">
    <limit lower="-3.1415" upper="3.1415" effort="54.0" velocity="3.14"/>
    <parent link="arm2_virtual_roll_link"/>
    <child link="arm2_virtual_yaw_link"/>
    <axis xyz="0 0 1"/>
    <origin xyz="0.02955 0.0 0.0" rpy="0 0 0"/>
    <dynamics damping="0.0" friction="0.0"/>
  </joint>

  <!-- Virtual yaw link -->
  <link name="arm2_virtual_yaw_link">
    <visual>
      <origin xyz="0.0 0 0.0" rpy="0 0 0"/>
      <geometry>
        <box size="0.01 0.01 0.01" />
      </geometry>
      <material name="red"/>
     </visual>

    <inertial>
      <origin xyz="0 0 0" />
      <mass value="1.0e-03" />
      <inertia ixx="1.0e-03" ixy="0.0" ixz="0.0"
               iyy="1.0e-03" iyz="0.0"
               izz="1.0e-03" />
    </inertial>
  </link>

  <gazebo reference="arm2_virtual_yaw_link">
    <material>Gazebo/Red</material>
  </gazebo>

  <!-- end effector joint -->
  <joint name="arm2_end_effector_joint" type="fixed">
    <origin xyz="0.0 0.0 0.0" rpy="0 0 0"/>
    <parent link="arm2_virtual_yaw_link"/>
    <child link="arm2_end_effector_link"/>
  </joint>

  <!-- end effector link -->
  <link name="arm2_end_effector_link">
    <visual>
      <origin xyz="0 0 0" rpy="0 0 0"/>
      <geometry>
        <box size="0.01 0.01 0.01" />
      </geometry>
      <material name="red"/>
     </visual>

    <inertial>
      <origin xyz="0 0 0" />
      <mass value="1.0e-03" />
      <inertia ixx="1.0e-03" ixy="0.0" ixz="0.0"
               iyy="1.0e-03" iyz="0.0"
               izz="1.0e-03" />
    </inertial>
  </link>

</robot>

